Workbook

Sheet Inputs
A1: Downside — Model Inputs
H2: Scenario Assumptions
A3: Company & Model Setup
B4: Variable | C4: Historical/Market Reference | D4: Active Assumption | E4: Unit | F4: Rationale | H4: Case Selected | I4: Downside
B5: Company Name | D5: ADT Inc. | E5: Text | F5: Company Under Analysis
B6: Ticker | D6: ADT | E6: Text | F6: Public Stock Ticker
B7: Industry | D7: Security & Monitoring Services | E7: Text | F7: Provides security monitoring, installation, and related services
B8: Last Historical Year | D8: 2025 | E8: Year | F8: Most recent completed fiscal year | H8: Driver | I8: Base | J8: Downside
B9: Forecast Period | D9: 5 | E9: Years | F9: Number of future years projected | H9: Revenue Growth | I9: 0.05 | J9: 0.02
B10: Currency | D10: USD | E10: Currency | F10: Currency used throughout the model | H10: Calc. EBITDA Margin | I10: 0.52 | J10: 0.48
H11: Exit EV / EBITDA | I11: 5.5 | J11: 4.5
A12: Operating Assumptions
B13: Revenue Growth | C13: =AVERAGE(Historical!C10:D10) -> 0.049888205 | D13: =IF($I$4="Downside",$J$9,$I$9) -> 0.02 | E13: % Year | F13: Underwriting assumptions: Base 5% growth, Downside 2%; historical reference is recent average growth. | H13: Subscriber cash assumptions | I13: % Revenue
B14: Calculated EBITDA Margin | C14: =Historical!D16 -> 0.52180192 | D14: =IF($I$4="Downside",$J$10,$I$10) -> 0.48 | E14: % Revenue | F14: Operating income + D&A; Base 52%, Downside 48%. Reported Adjusted EBITDA is reconciled separately. | H14: Dealer purchases | I14: =Historical!D78 -> 0.11630507
B15: D&A as % of Revenue | C15: =Historical!D14/Historical!D9 -> 0.26658623 | D15: 0.27 | E15: % Revenue | F15: Near 2025A level; recent D&A intensity has been declining | H15: Cost amortization | I15: =Historical!D79 -> 0.049243976
B16: Capex as % of Revenue | C16: =Historical!D23 -> 0.1114792 | D16: 0.12 | E16: % Revenue | F16: Slightly above 2025A to avoid assuming continued capex compression | H16: Revenue amortization | I16: =Historical!D80 -> 0.069885058
B17: Operating NWC as % of Revenue | C17: =Historical!D84 -> 0.093535535 | D17: =C17 -> 0.093535535 | E17: % Revenue | F17: AR + inventory - AP, calibrated to 2025. Deferred subscriber cash flows modeled separately. | H17: Deferred cash costs | I17: =Historical!D81 -> 0.074197341
B18: Tax Rate | C18: =Historical!D28 -> 0.27979209 | D18: 0.27 | E18: % | F18: Near 2025A rate and recent historical range | H18: Deferred cash receipts | I18: =Historical!D82 -> 0.04382925
A20: Transaction Assumptions | H20: Basis: 2025 intensity
B21: Valuation Date | C21: – | D21: 46022 | E21: Date | F21: Retrospective 12/31/2025 analysis using FY2025 10-K filed 03/02/2026; not information available at entry. | H21: Same rates in both cases
B22: Reference Share Price | C22: 8.07 | D22: – | E22: $ / Share | F22: 12/31/2025 close $8.07; Trading 212, corroborated by ChartExchange. Links at H41:H42.
B23: EV / EBITDA | C23: =I36 -> 5.3567735 | D23: 5.5 | E23: x EBITDA | F23: Market reference calculated at H26:I38; excludes finance leases/dilution. Entry 5.5x is a model assumption. | H23: EBITDA: income + D&A
B24: Transaction Fees | C24: – | D24: 0.02 | E24: % EV | F24: Model assumption: transaction fees equal 2% of enterprise value. | H24: Multiples are assumptions
B25: Minimum Cash | C25: 80.817 | D25: 100 | E25: $M | F25: Model assumption: $100M operating cash buffer; historical cash is $80.817M.
H26: Market Reference Build | I26: 46022
A27: Debt Assumptions | H27: Share price | I27: =$C$22 -> 8.07
B28: Entry Leverage | C28: =Historical!D42 -> 2.9143748 | D28: 4 | E28: x EBITDA | F28: Higher leverage than current capital structure to reflect hypothetical sponsor financing | H28: Common shares (M) | I28: 765.20116
B29: Blended Interest Rate | C29: =Historical!D45/AVERAGE(Historical!C41:D41) -> 0.052519028 | D29: 0.07 | E29: % / Year | F29: Model assumption: 7% financing cost. Historical ratio is cash interest / average debt, not a quoted borrowing rate. | H29: Class B shares (M) | I29: 54.744525
B30: Annual Mandatory Amortization | C30: – | D30: 0.01 | E30: % Initial Debt | F30: Model assumption: annual amortization of 1% of initial acquisition debt. | H30: Total shares (M) | I30: =SUM(I28:I29) -> 819.94568
B31: Excess Cash Sweep | C31: – | D31: 1 | E31: % Excess Cash | F31: Model assumption: 100% of excess cash swept to debt repayment. | H31: Equity value ($M) | I31: =I27*I30 -> 6616.9617
B32: Minimum DSCR | C32: – | D32: 1.25 | E32: x | F32: Internal underwriting warning threshold | H32: Debt principal ($M) | I32: =Historical!D41 -> 7799.208
B33: Maximum Debt / EBITDA | C33: =Historical!D42 -> 2.9143748 | D33: 5 | E33: x | F33: Internal leverage warning threshold | H33: Cash ($M) | I33: =Historical!D40 -> 80.817
H34: Enterprise value ($M) | I34: =I31+I32-I33 -> 14335.353
A35: Exit and Return Assumptions | H35: Calculated EBITDA | I35: =Historical!D15 -> 2676.117
B36: Holding Period | C36: N/A | D36: 5 | E36: Years | F36: Standard five-year sponsor holding period for base case | H36: EV / calc. EBITDA | I36: =I34/I35 -> 5.3567735
B37: Exit EV / EBITDA | C37: =Inputs!C23 -> 5.3567735 | D37: =IF($I$4="Downside",$J$11,$I$11) -> 4.5 | E37: x EBITDA | F37: Model assumptions: Base 5.5x, Downside 4.5x on calculated EBITDA. | H37: Adjusted EBITDA | I37: ='EBITDA Bridge'!B15 -> 2680.376
B38: Target IRR | C38: N/A | D38: 0.2 | E38: % | F38: Target annualized equity return for base-case underwriting | H38: EV / adj. EBITDA | I38: =I34/I37 -> 5.3482618
B39: Minimum Acceptable IRR | C39: N/A | D39: 0.15 | E39: % | F39: Downside threshold used to identify unacceptable equity returns
B40: Target MOIC | C40: N/A | D40: 2 | E40: x | F40: Reference equity multiple target | H40: Market sources and scope
H41: https://www.trading212.com/trading-instruments/invest/ADT.US
...

Sheet Historical
A2: ADT — Historical Financials
A4: Metric | B4: 2023A | C4: 2024A | D4: 2025A | E4: Notes
A6: Revenue
A7: Monitoring & Related Services | B7: 4178.998 | C7: 4293.477 | D7: 4354.087 | E7: $M; source: ADT 2025 10-K
A8: Security Installation, Product & Other | B8: 473.826 | C8: 604.969 | D8: 774.52 | E8: $M; source: ADT 2025 10-K
A9: Total Revenue | B9: =B7 + B8 -> 4652.824 | C9: =C7 + C8 -> 4898.446 | D9: =D7 + D8 -> 5128.607
A10: Revenue Growth | B10: N/A | C10: =C9/B9-1 -> 0.052789876 | D10: =D9/C9-1 -> 0.046986534 | E10: Year-over-year growth in total revenue
A12: Profitability
A13: Operating Income | B13: 1178.961 | C13: 1208.064 | D13: 1308.901 | E13: $M; source: ADT 2025 10-K
A14: Depreciation & Amortization | B14: 1335.484 | C14: 1342.798 | D14: 1367.216
A15: EBITDA (calculated) | B15: =B13 + B14 -> 2514.445 | C15: =C13 + C14 -> 2550.862 | D15: =D13 + D14 -> 2676.117 | E15: Operating income + D&A; differs from reported Adjusted EBITDA
A16: EBITDA Margin | B16: =B15/B9 -> 0.54041266 | C16: =C15/C9 -> 0.52074923 | D16: =D15/D9 -> 0.52180192 | E16: EBITDA divided by total revenue
A18: Cash Flow & Reinvestment
A19: Net Cash from Operating Activities | B19: 1657.726 | C19: 1884.899 | D19: 1884.163 | E19: Consolidated CFO, including discontinued operations; FY2025 10-K F-8.
A20: Subscriber System Asset Expenditures | B20: 630.535 | C20: 523.146 | D20: 395.986 | E20: $M; source: ADT 2025 10-K
A21: Purchases of Property and Equipment | B21: 176.353 | C21: 163.805 | D21: 175.747 | E21: Consolidated PP&E spending; older years include discontinued operations.
A22: Total Capex | B22: =B20 + B21 -> 806.888 | C22: =C20 + C21 -> 686.951 | D22: =D20 + D21 -> 571.733 | E22: Subscriber Systems + PP&E
A23: Capex as % of Revenue | B23: =B22 / B9 -> 0.17341898 | C23: =C22 / C9 -> 0.14023856 | D23: =D22 / D9 -> 0.1114792 | E23: Total capex divided by revenue
A25: Taxes
A26: Income Before Taxes | B26: 604.383 | C26: 815.17 | D26: 833.812 | E26: $M; source: ADT 2025 10-K
A27: Income Tax Expense | B27: 160.585 | C27: 195.78 | D27: 233.294 | E27: $M; source: ADT 2025 10-K
A28: Effective Tax Rate | B28: =B27/B26 -> 0.26570072 | C28: =C27/C26 -> 0.24017076 | D28: =D27/D26 -> 0.27979209
A30: Working Capital
A31: Accounts Receivable | B31: 370.201 | C31: 393.511 | D31: 384.909 | E31: FY2025 10-K for 2025/2024; FY2024 10-K for 2023 balance sheet.
A32: Inventory | B32: 201.394 | C32: 196.731 | D32: 201.778 | E32: FY2025 10-K for 2025/2024; FY2024 10-K for 2023 balance sheet.
A33: Accounts Payable | B33: 277.201 | C33: 153.537 | D33: 106.98 | E33: FY2025 10-K for 2025/2024; FY2024 10-K for 2023 balance sheet.
A34: Deferred Revenue | B34: 255.221 | C34: 247.785 | D34: 243.724 | E34: Current deferred revenue; FY2025/FY2024 10-K balance sheets.
A35: Operating NWC | B35: =B31 + B32 - B33 -B34 -> 39.173 | C35: =C31 + C32 - C33 -C34 -> 188.92 | D35: =D31 + D32 - D33 -D34 -> 235.983
A36: Operating NWC as % of Revenue- | B36: =B35/B9 -> 0.008419188 | C36: =C35/C9 -> 0.038567333 | D36: =D35/D9 -> 0.046013079
A37: Change in Operating NWC | B37: N/A | C37: =C35 - B35 -> 149.747 | D37: =D35 - C35 -> 47.063
A39: Capital Structures
A40: Cash & Cash Equivalents | B40: 14.621 | C40: 96.212 | D40: 80.817 | E40: Cash excludes restricted cash; FY2025/FY2024 10-K balance sheets.
A41: Total Debt Principal | B41: 7936.54 | C41: 7791.903 | D41: 7799.208 | E41: Debt principal excludes finance leases; FY2025/FY2024 10-K, Note 7.
A42: Gross Debt / EBITDA | B42: =B41 / B15 -> 3.1563784 | C42: =C41 / C15 -> 3.0546157 | D42: =D41 / D15 -> 2.9143748 | E42: Total debt principal / EBITDA
A43: Net Debt | B43: =B41-B40 -> 7921.919 | C43: =C41-C40 -> 7695.691 | D43: =D41-D40 -> 7718.391 | E43: Debt less cash
A44: Net Debt / EBITDA | B44: =B43/B15 -> 3.1505636 | C44: =C43/C15 -> 3.0168982 | D44: =D43/D15 -> 2.8841755 | E44: Net debt / EBITDA
A45: Cash Interest Paid | B45: 522.775 | C45: 372.036 | D45: 409.415 | E45: Net cash interest includes leases/swaps; FY2025 10-K supplementary cash flows.
A47: 2025 Cash Flow Reconciliation
D48: 2025A ($M) | E48: Source: ADT 2025 10-K, F-8; consolidated cash flows
A49: Net income | D49: 595.951 | E49: https://www.sec.gov/Archives/edgar/data/1703056/000170305626000022/adt-20251231.htm
...

Sheet EBITDA Bridge
A1: ADT — EBITDA Reconciliation | B1: 2025A ($M)
A2: Income from continuing operations | B2: 600.518
A3: Interest expense, net | B3: 459.266
A4: Income tax expense | B4: 233.294
A5: Depreciation and intangible asset amortization | B5: 1367.216
A6: Deferred subscriber acquisition cost amortization | B6: 252.553
A7: Deferred subscriber acquisition revenue amortization | B7: -358.413
A8: Share-based compensation | B8: 54.553
A9: Merger, restructuring, integration and other | B9: 13.145
A10: Goodwill impairment | B10: 12.023
A11: Unrealized loss on interest rate swaps | B11: 15.461
A12: Loss on extinguishment of debt | B12: 18.85
A13: Other adjustments, net | B13: 11.91
A14: Reconciled Adjusted EBITDA | B14: =SUM(B2:B13) -> 2680.376
A15: Reported Adjusted EBITDA | B15: 2680.376
A16: Reconciliation check | B16: =B14-B15 -> 0
A17: Our calculated EBITDA | B17: =Historical!D15 -> 2676.117
A18: Difference from our calculated EBITDA | B18: =B14-B17 -> 4.259
A20: Source: ADT 2025 Form 10-K, Non-GAAP Measures, p.60.
A21: https://www.sec.gov/Archives/edgar/data/1703056/000170305626000022/adt-20251231.htm
A23: Model basis: calculated EBITDA for valuation and leverage.
A24: Reported Adjusted EBITDA is shown for reconciliation.

Sheet Operating Model
A2: ADT - Operating Model
A4: Metric | B4: 2025A | C4: 2026E | D4: 2027E | E4: 2028E | F4: 2029E | G4: 2030E | H4: Notes
A6: Revenue
A7: Total Revenue | B7: =Historical!D9 -> 5128.607 | C7: =B7*(1 + Inputs!$D$13) -> 5231.1791 | D7: =C7*(1 + Inputs!$D$13) -> 5335.8027 | E7: =D7*(1 + Inputs!$D$13) -> 5442.5188 | F7: =E7*(1 + Inputs!$D$13) -> 5551.3692 | G7: =F7*(1 + Inputs!$D$13) -> 5662.3965
A8: Revenue Growth | B8: =B7/Historical!C9 -1 -> 0.046986534 | C8: =C7/B7 - 1 -> 0.02 | D8: =D7/C7 - 1 -> 0.02 | E8: =E7/D7 - 1 -> 0.02 | F8: =F7/E7 - 1 -> 0.02 | G8: =G7/F7 - 1 -> 0.02
A10: Profitability
A11: EBITDA (calculated) | B11: =Historical!$D$15 -> 2676.117 | C11: =C7*Inputs!$D$14 -> 2510.966 | D11: =D7*Inputs!$D$14 -> 2561.1853 | E11: =E7*Inputs!$D$14 -> 2612.409 | F11: =F7*Inputs!$D$14 -> 2664.6572 | G11: =G7*Inputs!$D$14 -> 2717.9503
A12: EBITDA Margin | B12: =Historical!D16 -> 0.52180192 | C12: =C11/C7 -> 0.48 | D12: =D11/D7 -> 0.48 | E12: =E11/E7 -> 0.48 | F12: =F11/F7 -> 0.48 | G12: =G11/G7 -> 0.48
A13: D&A | B13: =Historical!D14 -> 1367.216 | C13: =C7 * Inputs!$D$15 -> 1412.4184 | D13: =D7 * Inputs!$D$15 -> 1440.6667 | E13: =E7 * Inputs!$D$15 -> 1469.4801 | F13: =F7 * Inputs!$D$15 -> 1498.8697 | G13: =G7 * Inputs!$D$15 -> 1528.8471
A14: EBIT | B14: =Historical!D13 -> 1308.901 | C14: =C11-C13 -> 1098.5476 | D14: =D11-D13 -> 1120.5186 | E14: =E11-E13 -> 1142.9289 | F14: =F11-F13 -> 1165.7875 | G14: =G11-G13 -> 1189.1033
A16: Reinvestment & Unlevered Cash Flow
A17: Tax Rate | B17: =Historical!D28 -> 0.27979209 | C17: =Inputs!$D$18 -> 0.27 | D17: =Inputs!$D$18 -> 0.27 | E17: =Inputs!$D$18 -> 0.27 | F17: =Inputs!$D$18 -> 0.27 | G17: =Inputs!$D$18 -> 0.27
A18: NOPAT | B18: =B14*(1-B17) -> 942.68086 | C18: =C14*(1-C17) -> 801.93976 | D18: =D14*(1-D17) -> 817.97856 | E18: =E14*(1-E17) -> 834.33813 | F18: =F14*(1-F17) -> 851.02489 | G18: =G14*(1-G17) -> 868.04539
A19: System and equipment capex | B19: =Historical!D22 -> 571.733 | C19: =C7*Inputs!$D$16 -> 627.7415 | D19: =D7*Inputs!$D$16 -> 640.29633 | E19: =E7*Inputs!$D$16 -> 653.10225 | F19: =F7*Inputs!$D$16 -> 666.1643 | G19: =G7*Inputs!$D$16 -> 679.48758
A20: Trade NWC (excl. deferred revenue) | B20: =Historical!D83 -> 479.707 | C20: =C7*Inputs!$D$17 -> 489.30114 | D20: =D7*Inputs!$D$17 -> 499.08716 | E20: =E7*Inputs!$D$17 -> 509.06891 | F20: =F7*Inputs!$D$17 -> 519.25028 | G20: =G7*Inputs!$D$17 -> 529.63529
A21: Change in Operating NWC | B21: =Historical!D83-(Historical!C31+Historical!C32-Historical!C33) -> 43.002 | C21: =C20-B20 -> 9.59414 | D21: =D20-C20 -> 9.7860228 | E21: =E20-D20 -> 9.9817433 | F21: =F20-E20 -> 10.181378 | G21: =G20-F20 -> 10.385006
A22: Unlevered Free Cash Flow | B22: =B18+B13-B19-B21-B25+B30 -> 837.07286 | C22: =C18+C13-C19-C21-C25+C30 -> 701.77171 | D22: =D18+D13-D19-D21-D25+D30 -> 715.80715 | E22: =E18+E13-E19-E21-E25+E30 -> 730.12329 | F22: =F18+F13-F19-F21-F25+F30 -> 744.72576 | G22: =G18+G13-G19-G21-G25+G30 -> 759.62027
A24: Subscriber Cash Flow Adjustments
A25: Dealer-account purchases | B25: =Historical!D73 -> 596.483 | C25: =C7*Inputs!$I$14 -> 608.41266 | D25: =D7*Inputs!$I$14 -> 620.58091 | E25: =E7*Inputs!$I$14 -> 632.99253 | F25: =F7*Inputs!$I$14 -> 645.65238 | G25: =G7*Inputs!$I$14 -> 658.56543
A26: Cost amortization add-back | B26: =Historical!D51 -> 252.553 | C26: =C7*Inputs!$I$15 -> 257.60406 | D26: =D7*Inputs!$I$15 -> 262.75614 | E26: =E7*Inputs!$I$15 -> 268.01126 | F26: =F7*Inputs!$I$15 -> 273.37149 | G26: =G7*Inputs!$I$15 -> 278.83892
A27: Revenue amortization removal | B27: =-Historical!D52 -> 358.413 | C27: =C7*Inputs!$I$16 -> 365.58126 | D27: =D7*Inputs!$I$16 -> 372.89289 | E27: =E7*Inputs!$I$16 -> 380.35074 | F27: =F7*Inputs!$I$16 -> 387.95776 | G27: =G7*Inputs!$I$16 -> 395.71691
A28: Deferred acquisition cash costs | B28: =-Historical!D67 -> 380.529 | C28: =C7*Inputs!$I$17 -> 388.13958 | D28: =D7*Inputs!$I$17 -> 395.90237 | E28: =E7*Inputs!$I$17 -> 403.82042 | F28: =F7*Inputs!$I$17 -> 411.89683 | G28: =G7*Inputs!$I$17 -> 420.13476
A29: Deferred acquisition cash receipts | B29: =Historical!D68 -> 224.783 | C29: =C7*Inputs!$I$18 -> 229.27866 | D29: =D7*Inputs!$I$18 -> 233.86423 | E29: =E7*Inputs!$I$18 -> 238.54152 | F29: =F7*Inputs!$I$18 -> 243.31235 | G29: =G7*Inputs!$I$18 -> 248.1786
A30: Net deferred acquisition adjustment | B30: =B26-B27-B28+B29 -> -261.606 | C30: =C26-C27-C28+C29 -> -266.83812 | D30: =D26-D27-D28+D29 -> -272.17488 | E30: =E26-E27-E28+E29 -> -277.61838 | F30: =F26-F27-F28+F29 -> -283.17075 | G30: =G26-G27-G28+G29 -> -288.83416
H32: Subscriber rates follow 2025 revenue intensity; trade NWC excludes deferred revenue.
H33: Cash tax and other working-capital items remain simplified; historical UFCF is modeled, not reported.

Sheet Transaction
A2: ADT — Transaction Overview
A4: Entry Valuation
A5: Metric | B5: Value | C5: Unit | D5: Notes
A6: 2025A Calculated EBITDA | B6: ='Operating Model'!B11 -> 2676.117 | C6: $M | D6: Operating income + D&A; entry leverage and EV use this definition.
A7: Entry EV / EBITDA | B7: =Inputs!D23 -> 5.5 | C7: x | D7: Underwriting multiple on calculated EBITDA.
A8: Entry Enterprise Value | B8: =B6 * B7 -> 14718.644 | C8: $M | D8: 2025A EBITDA x entry multiple
A9: Existing Debt | B9: =Historical!D41 -> 7799.208 | C9: $M | D9: Existing debt refinanced at closing
A10: Cash & Cash Equivalents | B10: =Historical!D40 -> 80.817 | C10: $M | D10: Existing cash available at closing
A11: Implied Equity Purchase Price | B11: =B8 - B9+B10 -> 7000.2525 | C11: $M | D11: Enterprise value − debt + cash
A13: Uses | E13: Sources
A14: Use | B14: Amount ($M) | C14: Notes | E14: Source | F14: Amount ($M) | G14: Notes
A15: Purchase Equity Value | B15: =B11 -> 7000.2525 | E15: New Debt | F15: =B6*Inputs!$D$28 -> 10704.468
A16: Refinance Existing Debt | B16: =B9 -> 7799.208 | E16: Target Cash | F16: =B10 -> 80.817
A17: Transaction Fees | B17: =B8 * Inputs!$D$24 -> 294.37287 | E17: Sponsor Equity | F17: =B19-F15-F16 -> 4408.5484
A18: Minimum Cash | B18: =Inputs!D25 -> 100
A19: Total Uses | B19: =SUM(B15:B18) -> 15193.833 | E19: Total Sources | F19: =SUM(F15:F17) -> 15193.833
A21: Sources − Uses Check | B21: =F19-B19 -> 0

Sheet Debt Schedule
A2: ADT — Debt Schedule
A4: Metric | B4: 2026E | C4: 2027E | D4: 2028E | E4: 2029E | F4: 2030E
A6: Beginning Debt | B6: =Transaction!F15 -> 10704.468 | C6: =B19 -> 10549.695 | D6: =C19 -> 10372.977 | E6: =D19 -> 10172.913 | F6: =E19 -> 9948.0228
A7: Interest Rate | B7: =Inputs!$D$29 -> 0.07 | C7: =Inputs!$D$29 -> 0.07 | D7: =Inputs!$D$29 -> 0.07 | E7: =Inputs!$D$29 -> 0.07 | F7: =Inputs!$D$29 -> 0.07
A8: Cash Interest Expense | B8: =B6*B7 -> 749.31276 | C8: =C6*C7 -> 738.47862 | D8: =D6*D7 -> 726.10838 | E8: =E6*E7 -> 712.10389 | F8: =F6*F7 -> 696.36159
A10: Unlevered Free Cash Flow | B10: ='Operating Model'!C22 -> 701.77171 | C10: ='Operating Model'!D22 -> 715.80715 | D10: ='Operating Model'!E22 -> 730.12329 | E10: ='Operating Model'!F22 -> 744.72576 | F10: ='Operating Model'!G22 -> 759.62027
A11: Tax Rate | B11: ='Operating Model'!C17 -> 0.27 | C11: ='Operating Model'!D17 -> 0.27 | D11: ='Operating Model'!E17 -> 0.27 | E11: ='Operating Model'!F17 -> 0.27 | F11: ='Operating Model'!G17 -> 0.27
A12: Cash Flow After Interest | B12: =B10-B8*(1-B11) -> 154.7734 | C12: =C10-C8*(1-C11) -> 176.71775 | D12: =D10-D8*(1-D11) -> 200.06417 | E12: =E10-E8*(1-E11) -> 224.88992 | F12: =F10-F8*(1-F11) -> 251.27631
A14: Mandatory Amortization | B14: =MIN(B6, Transaction!$F$15*Inputs!$D$30) -> 107.04468 | C14: =MIN(C6, Transaction!$F$15*Inputs!$D$30) -> 107.04468 | D14: =MIN(D6, Transaction!$F$15*Inputs!$D$30) -> 107.04468 | E14: =MIN(E6,Transaction!$F$15*Inputs!$D$30) -> 107.04468 | F14: =MIN(F6,Transaction!$F$15*Inputs!$D$30) -> 107.04468
A15: Cash Available for Sweep | B15: =MAX(0, B12-B14) -> 47.728718 | C15: =MAX(0, C12-C14) -> 69.673073 | D15: =MAX(0, D12-D14) -> 93.019493 | E15: =MAX(0, E12-E14) -> 117.84524 | F15: =MAX(0, F12-F14) -> 144.23163
A16: Cash Sweep % | B16: =Inputs!$D$31 -> 1 | C16: =Inputs!$D$31 -> 1 | D16: =Inputs!$D$31 -> 1 | E16: =Inputs!$D$31 -> 1 | F16: =Inputs!$D$31 -> 1
A17: Optional Debt Repayment | B17: =MIN(MAX(0, B6-B14),B15*B16) -> 47.728718 | C17: =MIN(MAX(0, C6-C14),C15*C16) -> 69.673073 | D17: =MIN(MAX(0, D6-D14),D15*D16) -> 93.019493 | E17: =MIN(MAX(0, E6-E14),E15*E16) -> 117.84524 | F17: =MIN(MAX(0, F6-F14),F15*F16) -> 144.23163
A19: Ending Debt | B19: =B6-B14-B17 -> 10549.695 | C19: =C6-C14-C17 -> 10372.977 | D19: =D6-D14-D17 -> 10172.913 | E19: =E6-E14-E17 -> 9948.0228 | F19: =F6-F14-F17 -> 9696.7464
A21: EBITDA (calculated) | B21: ='Operating Model'!C11 -> 2510.966 | C21: ='Operating Model'!D11 -> 2561.1853 | D21: ='Operating Model'!E11 -> 2612.409 | E21: ='Operating Model'!F11 -> 2664.6572 | F21: ='Operating Model'!G11 -> 2717.9503
A22: Debt / EBITDA | B22: =B19/B21 -> 4.2014486 | C22: =C19/C21 -> 4.0500689 | D22: =D19/D21 -> 3.8940735 | E22: =E19/E21 -> 3.7333218 | F22: =F19/F21 -> 3.5676687
A23: DSCR | B23: =(B12+B8)/(B8+B14) -> 1.0557346 | C23: =(C12+C8)/(C8+C14) -> 1.0824023 | D23: =(D12+D8)/(D8+D14) -> 1.1116475 | E23: =(E12+E8)/(E8+E14) -> 1.1438631 | F23: =(F12+F8)/(F8+F14) -> 1.1795251
A25: Interest uses beginning debt; cash flow includes the interest tax shield.
A27: Debt Roll-forward Check | B27: =B6-B14-B17-B19 -> 0 | C27: =C6-C14-C17-C19 -> 0 | D27: =D6-D14-D17-D19 -> 0 | E27: =E6-E14-E17-E19 -> 0 | F27: =F6-F14-F17-F19 -> 0
A28: Repayment Limit Check | B28: =MAX(0,B14+B17-B6,-B14,-B17,-B19) -> 0 | C28: =MAX(0,C14+C17-C6,-C14,-C17,-C19) -> 0 | D28: =MAX(0,D14+D17-D6,-D14,-D17,-D19) -> 0 | E28: =MAX(0,E14+E17-E6,-E14,-E17,-E19) -> 0 | F28: =MAX(0,F14+F17-F6,-F14,-F17,-F19) -> 0

Sheet Returns
A2: ADT — Sponsor Returns
A4: Metric | B4: Value | C4: Unit | D4: Notes
A6: Initial Sponsor Equity | B6: =Transaction!F17 -> 4408.5484 | C6: $M
A7: Holding Period | B7: =Inputs!D36 -> 5 | C7: Years
A9: Exit EBITDA | B9: ='Operating Model'!G11 -> 2717.9503 | C9: $M | D9: 2030 calculated EBITDA: operating income + D&A.
A10: Exit EV / EBITDA | B10: =Inputs!D37 -> 4.5 | C10: x | D10: Underwriting exit multiple on calculated EBITDA.
A11: Exit Enterprise Value | B11: =B9*B10 -> 12230.777 | C11: $M
A12: Exit Debt | B12: ='Debt Schedule'!F19 -> 9696.7464 | C12: $M
A13: Exit Cash | B13: =Inputs!D25 -> 100 | C13: $M | D13: Minimum cash retained; no interim distributions assumed
A14: Sponsor Exit Proceeds | B14: =B11-B12+B13 -> 2634.0301 | C14: $M
A17: MOIC | B17: =B14/B6 -> 0.5974824 | C17: x
A18: Annualized IRR | B18: =B17^(1/B7)-1 -> -0.09787852 | C18: %
A20: Assumes a 2030 exit, no exit fees, and full sponsor ownership.

Sheet Downside
A2: ADT — Downside Analysis
A4: Case Selected | B4: =Inputs!I4 -> Downside
A6: Assumption | B6: Base | C6: Downside
A7: Revenue Growth | B7: =Inputs!I9 -> 0.05 | C7: =Inputs!J9 -> 0.02
A8: EBITDA Margin | B8: =Inputs!I10 -> 0.52 | C8: =Inputs!J10 -> 0.48
A9: Exit EV / EBITDA | B9: =Inputs!I11 -> 5.5 | C9: =Inputs!J11 -> 4.5
A12: Metric | B12: Selected Case | C12: Threshold | D12: Assessment
A13: Sponsor Equity Invested ($M) | B13: =Returns!B6 -> 4408.5484
A14: Exit EBITDA ($M) | B14: =Returns!B9 -> 2717.9503
A15: Exit Debt ($M) | B15: =Returns!B12 -> 9696.7464
A16: Sponsor Exit Proceeds ($M) | B16: =Returns!B14 -> 2634.0301
A17: MOIC | B17: =Returns!B17 -> 0.5974824 | C17: =Inputs!D40 -> 2 | D17: =IF(B17>=C17, "Meets target", "Below target") -> Below target
A18: IRR | B18: =Returns!B18 -> -0.09787852 | C18: =Inputs!D39 -> 0.15 | D18: =IF(B18>=C18, "Pass", "Below minimum") -> Below minimum
A19: Minimum DSCR | B19: =MIN('Debt Schedule'!B23:F23) -> 1.0557346 | C19: =Inputs!D32 -> 1.25 | D19: =IF(B19>=C19, "Pass", "Below minimum") -> Below minimum
A20: Maximum Year-end Debt / EBITDA | B20: =MAX('Debt Schedule'!B22:F22) -> 4.2014486 | C20: =Inputs!D33 -> 5 | D20: =IF(B20<=C20, "Pass", "Above maximum") -> Pass
A23: Stress case: 2% growth, 48% EBITDA margin, and 4.5x exit multiple.
A24: Entry price and acquisition financing are unchanged between cases.

Sheet Dashboard
A2: ADT — Investment Dashboard
A4: Case Selected | B4: =Inputs!I4 -> Downside
A6: Investment Returns
A7: MOIC | B7: =Returns!B17 -> 0.5974824 | C7: MOIC target | D7: =Inputs!D40 -> 2
A8: Annualized IRR | B8: =Returns!B18 -> -0.09787852 | C8: Minimum IRR | D8: =Inputs!D39 -> 0.15
C9: Target IRR | D9: =Inputs!D38 -> 0.2
A10: Debt Risk
A11: Minimum DSCR | B11: =Downside!B19 -> 1.0557346 | C11: Minimum DSCR | D11: =Inputs!D32 -> 1.25
A12: Maximum Year-end Leverage | B12: =Downside!B20 -> 4.2014486 | C12: Maximum leverage | D12: =Inputs!D33 -> 5
A14: Transaction ($M)
A15: Sponsor Equity Invested | B15: =Transaction!F17 -> 4408.5484
A16: Entry Enterprise Value | B16: =Transaction!B8 -> 14718.644
A17: Exit Debt | B17: =Returns!B12 -> 9696.7464
G18: Exit Valuation Sensitivity — IRR
A19: Model Checks | G19: EBITDA change | H19: 3.5 | I19: 4 | J19: 4.5 | K19: 5 | L19: 5.5
A20: Sources − Uses | B20: =Transaction!B21 -> 0 | G20: -0.2 | H20: =(MAX(0,Returns!$B$9*(1+$G20)*H$19-Returns!$B$12+Returns!$B$13)/Returns!$B$6)^(1/Returns!$B$7)-1 -> -1 | I20: =(MAX(0,Returns!$B$9*(1+$G20)*I$19-Returns!$B$12+Returns!$B$13)/Returns!$B$6)^(1/Returns!$B$7)-1 -> -1 | J20: =(MAX(0,Returns!$B$9*(1+$G20)*J$19-Returns!$B$12+Returns!$B$13)/Returns!$B$6)^(1/Returns!$B$7)-1 -> -0.4679964 | K20: =(MAX(0,Returns!$B$9*(1+$G20)*K$19-Returns!$B$12+Returns!$B$13)/Returns!$B$6)^(1/Returns!$B$7)-1 -> -0.21972686 | L20: =(MAX(0,Returns!$B$9*(1+$G20)*L$19-Returns!$B$12+Returns!$B$13)/Returns!$B$6)^(1/Returns!$B$7)-1 -> -0.1173155
A21: Debt Checks | B21: =IF(AND(COUNT('Debt Schedule'!B27:F28)=10,MAX('Debt Schedule'!B27:F28)<=0.01,MIN('Debt Schedule'!B27:F28)>=-0.01),"Pass","Review") -> Pass | G21: -0.1 | H21: =(MAX(0,Returns!$B$9*(1+$G21)*H$19-Returns!$B$12+Returns!$B$13)/Returns!$B$6)^(1/Returns!$B$7)-1 -> -1 | I21: =(MAX(0,Returns!$B$9*(1+$G21)*I$19-Returns!$B$12+Returns!$B$13)/Returns!$B$6)^(1/Returns!$B$7)-1 -> -0.4679964 | J21: =(MAX(0,Returns!$B$9*(1+$G21)*J$19-Returns!$B$12+Returns!$B$13)/Returns!$B$6)^(1/Returns!$B$7)-1 -> -0.20376117 | K21: =(MAX(0,Returns!$B$9*(1+$G21)*K$19-Returns!$B$12+Returns!$B$13)/Returns!$B$6)^(1/Returns!$B$7)-1 -> -0.09787852 | L21: =(MAX(0,Returns!$B$9*(1+$G21)*L$19-Returns!$B$12+Returns!$B$13)/Returns!$B$6)^(1/Returns!$B$7)-1 -> -0.026371604
G22: 0 | H22: =(MAX(0,Returns!$B$9*(1+$G22)*H$19-Returns!$B$12+Returns!$B$13)/Returns!$B$6)^(1/Returns!$B$7)-1 -> -1 | I22: =(MAX(0,Returns!$B$9*(1+$G22)*I$19-Returns!$B$12+Returns!$B$13)/Returns!$B$6)^(1/Returns!$B$7)-1 -> -0.21972686 | J22: =(MAX(0,Returns!$B$9*(1+$G22)*J$19-Returns!$B$12+Returns!$B$13)/Returns!$B$6)^(1/Returns!$B$7)-1 -> -0.09787852 | K22: =(MAX(0,Returns!$B$9*(1+$G22)*K$19-Returns!$B$12+Returns!$B$13)/Returns!$B$6)^(1/Returns!$B$7)-1 -> -0.019605528 | L22: =(MAX(0,Returns!$B$9*(1+$G22)*L$19-Returns!$B$12+Returns!$B$13)/Returns!$B$6)^(1/Returns!$B$7)-1 -> 0.039546166
A23: Investment Assessment | B23: =IF(AND(B7>=D7,B8>=D8,B11>=D11,B12<=D12),"Meets all thresholds","Does not meet all thresholds") -> Does not meet all thresholds | G23: 0.1 | H23: =(MAX(0,Returns!$B$9*(1+$G23)*H$19-Returns!$B$12+Returns!$B$13)/Returns!$B$6)^(1/Returns!$B$7)-1 -> -0.27759459 | I23: =(MAX(0,Returns!$B$9*(1+$G23)*I$19-Returns!$B$12+Returns!$B$13)/Returns!$B$6)^(1/Returns!$B$7)-1 -> -0.1173155 | J23: =(MAX(0,Returns!$B$9*(1+$G23)*J$19-Returns!$B$12+Returns!$B$13)/Returns!$B$6)^(1/Returns!$B$7)-1 -> -0.026371604 | K23: =(MAX(0,Returns!$B$9*(1+$G23)*K$19-Returns!$B$12+Returns!$B$13)/Returns!$B$6)^(1/Returns!$B$7)-1 -> 0.039546166 | L23: =(MAX(0,Returns!$B$9*(1+$G23)*L$19-Returns!$B$12+Returns!$B$13)/Returns!$B$6)^(1/Returns!$B$7)-1 -> 0.092041342
G24: 0.2 | H24: =(MAX(0,Returns!$B$9*(1+$G24)*H$19-Returns!$B$12+Returns!$B$13)/Returns!$B$6)^(1/Returns!$B$7)-1 -> -0.16229624 | I24: =(MAX(0,Returns!$B$9*(1+$G24)*I$19-Returns!$B$12+Returns!$B$13)/Returns!$B$6)^(1/Returns!$B$7)-1 -> -0.047883762 | J24: =(MAX(0,Returns!$B$9*(1+$G24)*J$19-Returns!$B$12+Returns!$B$13)/Returns!$B$6)^(1/Returns!$B$7)-1 -> 0.028766443 | K24: =(MAX(0,Returns!$B$9*(1+$G24)*K$19-Returns!$B$12+Returns!$B$13)/Returns!$B$6)^(1/Returns!$B$7)-1 -> 0.087671504 | L24: =(MAX(0,Returns!$B$9*(1+$G24)*L$19-Returns!$B$12+Returns!$B$13)/Returns!$B$6)^(1/Returns!$B$7)-1 -> 0.13603591
G26: Sensitivity holds exit debt and cash fixed; it tests sale valuation only.
A27: Base vs. Downside Comparison | G27: Operating stress is tested separately through the Base/Downside selector.
A28: Metric | B28: Base | C28: Downside
A29: Exit EBITDA ($M) | B29: ='Scenario Comparison'!B9 -> 3403.6842 | C29: ='Scenario Comparison'!C9 -> 2717.9503
A30: Exit Debt ($M) | B30: ='Scenario Comparison'!B10 -> 8462.2108 | C30: ='Scenario Comparison'!C10 -> 9696.7464
A31: Sponsor Exit Proceeds ($M) | B31: ='Scenario Comparison'!B11 -> 10358.052 | C31: ='Scenario Comparison'!C11 -> 2634.0301
A32: MOIC | B32: ='Scenario Comparison'!B12 -> 2.3495381 | C32: ='Scenario Comparison'!C12 -> 0.5974824
A33: Annualized IRR | B33: ='Scenario Comparison'!B13 -> 0.18630538 | C33: ='Scenario Comparison'!C13 -> -0.09787852
A34: Minimum DSCR | B34: ='Scenario Comparison'!B14 -> 1.24698 | C34: ='Scenario Comparison'!C14 -> 1.0557346
A100: Year | B100: Revenue ($M) | C100: EBITDA ($M) | G100: Base vs. Downside Debt
A101: {=INDEX('Operating Model'!$C$4:$G$4,1,ROWS($A$101:A101))} -> 2026E | B101: {=INDEX('Operating Model'!$C$7:$G$7,1,ROWS($A$101:A101))} -> 5231.1791 | C101: {=INDEX('Operating Model'!$C$11:$G$11,1,ROWS($A$101:A101))} -> 2510.966 | G101: Year | H101: Base | I101: Downside
A102: ='Operating Model'!D4 -> 2027E | B102: {=INDEX('Operating Model'!$C$7:$G$7,1,ROWS($A$101:A102))} -> 5335.8027 | C102: {=INDEX('Operating Model'!$C$11:$G$11,1,ROWS($A$101:A102))} -> 2561.1853 | G102: ='Scenario Comparison'!B34 -> 2026E | H102: ='Scenario Comparison'!B43 -> 10385.92 | I102: ='Scenario Comparison'!I43 -> 10549.695
A103: ='Operating Model'!E4 -> 2028E | B103: {=INDEX('Operating Model'!$C$7:$G$7,1,ROWS($A$101:A103))} -> 5442.5188 | C103: {=INDEX('Operating Model'!$C$11:$G$11,1,ROWS($A$101:A103))} -> 2612.409 | G103: ='Scenario Comparison'!C34 -> 2027E | H103: ='Scenario Comparison'!C43 -> 10007.817 | I103: ='Scenario Comparison'!J43 -> 10372.977
A104: ='Operating Model'!F4 -> 2029E | B104: {=INDEX('Operating Model'!$C$7:$G$7,1,ROWS($A$101:A104))} -> 5551.3692 | C104: {=INDEX('Operating Model'!$C$11:$G$11,1,ROWS($A$101:A104))} -> 2664.6572 | G104: ='Scenario Comparison'!D34 -> 2028E | H104: ='Scenario Comparison'!D43 -> 9564.9522 | I104: ='Scenario Comparison'!K43 -> 10172.913
A105: ='Operating Model'!G4 -> 2030E | B105: {=INDEX('Operating Model'!$C$7:$G$7,1,ROWS($A$101:A105))} -> 5662.3965 | C105: {=INDEX('Operating Model'!$C$11:$G$11,1,ROWS($A$101:A105))} -> 2717.9503 | G105: ='Scenario Comparison'!E34 -> 2029E | H105: ='Scenario Comparison'!E43 -> 9051.7434 | I105: ='Scenario Comparison'!L43 -> 9948.0228
G106: ='Scenario Comparison'!F34 -> 2030E | H106: ='Scenario Comparison'!F43 -> 8462.2108 | I106: ='Scenario Comparison'!M43 -> 9696.7464
F110: Equity IRR | G110: Target IRR | I110: Scenario | J110: Base | K110: Downside
E111: Base | F111: ='Scenario Comparison'!B13 -> 0.18630538 | G111: =Inputs!$D$38 -> 0.2 | I111: Base | J111: =F111 -> 0.18630538
E112: Downside | F112: ='Scenario Comparison'!C13 -> -0.09787852 | G112: =Inputs!$D$38 -> 0.2 | I112: Downside | K112: =F112 -> -0.09787852

Sheet Scenario Comparison
A2: ADT — Base vs. Downside
A4: Metric | B4: Base | C4: Downside
A5: Revenue Growth | B5: =Inputs!I9 -> 0.05 | C5: =Inputs!J9 -> 0.02
A6: EBITDA Margin | B6: =Inputs!I10 -> 0.52 | C6: =Inputs!J10 -> 0.48
A7: Exit EV / EBITDA | B7: =Inputs!I11 -> 5.5 | C7: =Inputs!J11 -> 4.5
A9: Exit EBITDA ($M) | B9: =F22 -> 3403.6842 | C9: =M22 -> 2717.9503
A10: Exit Debt ($M) | B10: =F43 -> 8462.2108 | C10: =M43 -> 9696.7464
A11: Sponsor Exit Proceeds ($M) | B11: =B9*$B$7-B10+Inputs!$D$25 -> 10358.052 | C11: =C9*$C$7-C10+Inputs!$D$25 -> 2634.0301
A12: MOIC | B12: =B11/Transaction!$F$17 -> 2.3495381 | C12: =C11/Transaction!$F$17 -> 0.5974824
A13: Annualized IRR | B13: =B12^(1/Inputs!$D$36)-1 -> 0.18630538 | C13: =C12^(1/Inputs!$D$36)-1 -> -0.09787852
A14: Minimum DSCR | B14: =MIN(B44:F44) -> 1.24698 | C14: =MIN(I44:M44) -> 1.0557346
A18: Base Case Calculations | H18: Downside Calculations
A20: Metric | B20: 2026E | C20: 2027E | D20: 2028E | E20: 2029E | F20: 2030E | H20: Metric | I20: 2026E | J20: 2027E | K20: 2028E | L20: 2029E | M20: 2030E
A21: Revenue | B21: ='Operating Model'!$B$7*(1+$B$5) -> 5385.0374 | C21: =B21*(1+$B$5) -> 5654.2892 | D21: =C21*(1+$B$5) -> 5937.0037 | E21: =D21*(1+$B$5) -> 6233.8539 | F21: =E21*(1+$B$5) -> 6545.5466 | H21: Revenue | I21: ='Operating Model'!$B$7*(1+$C$5) -> 5231.1791 | J21: =I21*(1+$C$5) -> 5335.8027 | K21: =J21*(1+$C$5) -> 5442.5188 | L21: =K21*(1+$C$5) -> 5551.3692 | M21: =L21*(1+$C$5) -> 5662.3965
A22: EBITDA (calculated) | B22: =B21*$B$6 -> 2800.2194 | C22: =C21*$B$6 -> 2940.2304 | D22: =D21*$B$6 -> 3087.2419 | E22: =E21*$B$6 -> 3241.604 | F22: =F21*$B$6 -> 3403.6842 | H22: EBITDA (calculated) | I22: =I21*$C$6 -> 2510.966 | J22: =J21*$C$6 -> 2561.1853 | K22: =K21*$C$6 -> 2612.409 | L22: =L21*$C$6 -> 2664.6572 | M22: =M21*$C$6 -> 2717.9503
A23: D&A | B23: =B21*Inputs!$D$15 -> 1453.9601 | C23: =C21*Inputs!$D$15 -> 1526.6581 | D23: =D21*Inputs!$D$15 -> 1602.991 | E23: =E21*Inputs!$D$15 -> 1683.1405 | F23: =F21*Inputs!$D$15 -> 1767.2976 | H23: D&A | I23: =I21*Inputs!$D$15 -> 1412.4184 | J23: =J21*Inputs!$D$15 -> 1440.6667 | K23: =K21*Inputs!$D$15 -> 1469.4801 | L23: =L21*Inputs!$D$15 -> 1498.8697 | M23: =M21*Inputs!$D$15 -> 1528.8471
A24: EBIT | B24: =B22-B23 -> 1346.2593 | C24: =C22-C23 -> 1413.5723 | D24: =D22-D23 -> 1484.2509 | E24: =E22-E23 -> 1558.4635 | F24: =F22-F23 -> 1636.3866 | H24: EBIT | I24: =I22-I23 -> 1098.5476 | J24: =J22-J23 -> 1120.5186 | K24: =K22-K23 -> 1142.9289 | L24: =L22-L23 -> 1165.7875 | M24: =M22-M23 -> 1189.1033
A25: Tax Rate | B25: =Inputs!$D$18 -> 0.27 | C25: =Inputs!$D$18 -> 0.27 | D25: =Inputs!$D$18 -> 0.27 | E25: =Inputs!$D$18 -> 0.27 | F25: =Inputs!$D$18 -> 0.27 | H25: Tax Rate | I25: =Inputs!$D$18 -> 0.27 | J25: =Inputs!$D$18 -> 0.27 | K25: =Inputs!$D$18 -> 0.27 | L25: =Inputs!$D$18 -> 0.27 | M25: =Inputs!$D$18 -> 0.27
A26: NOPAT | B26: =B24*(1-B25) -> 982.76932 | C26: =C24*(1-C25) -> 1031.9078 | D26: =D24*(1-D25) -> 1083.5032 | E26: =E24*(1-E25) -> 1137.6783 | F26: =F24*(1-F25) -> 1194.5622 | H26: NOPAT | I26: =I24*(1-I25) -> 801.93976 | J26: =J24*(1-J25) -> 817.97856 | K26: =K24*(1-K25) -> 834.33813 | L26: =L24*(1-L25) -> 851.02489 | M26: =M24*(1-M25) -> 868.04539
A27: System/equipment capex | B27: =B21*Inputs!$D$16 -> 646.20448 | C27: =C21*Inputs!$D$16 -> 678.51471 | D27: =D21*Inputs!$D$16 -> 712.44044 | E27: =E21*Inputs!$D$16 -> 748.06246 | F27: =F21*Inputs!$D$16 -> 785.46559 | H27: System/equipment capex | I27: =I21*Inputs!$D$16 -> 627.7415 | J27: =J21*Inputs!$D$16 -> 640.29633 | K27: =K21*Inputs!$D$16 -> 653.10225 | L27: =L21*Inputs!$D$16 -> 666.1643 | M27: =M21*Inputs!$D$16 -> 679.48758
A28: Trade NWC | B28: =B21*Inputs!$D$17 -> 503.69235 | C28: =C21*Inputs!$D$17 -> 528.87697 | D28: =D21*Inputs!$D$17 -> 555.32082 | E28: =E21*Inputs!$D$17 -> 583.08686 | F28: =F21*Inputs!$D$17 -> 612.2412 | H28: Trade NWC | I28: =I21*Inputs!$D$17 -> 489.30114 | J28: =J21*Inputs!$D$17 -> 499.08716 | K28: =K21*Inputs!$D$17 -> 509.06891 | L28: =L21*Inputs!$D$17 -> 519.25028 | M28: =M21*Inputs!$D$17 -> 529.63529
A29: Change in NWC | B29: =B28-'Operating Model'!$B$20 -> 23.98535 | C29: =C28-B28 -> 25.184618 | D29: =D28-C28 -> 26.443848 | E29: =E28-D28 -> 27.766041 | F29: =F28-E28 -> 29.154343 | H29: Change in NWC | I29: =I28-'Operating Model'!$B$20 -> 9.59414 | J29: =J28-I28 -> 9.7860228 | K29: =K28-J28 -> 9.9817433 | L29: =L28-K28 -> 10.181378 | M29: =M28-L28 -> 10.385006
A30: Unlevered Free Cash Flow | B30: =B26+B23-B27-B29-B49+B54 -> 865.54612 | C30: =C26+C23-C27-C29-C49+C54 -> 908.82342 | D30: =D26+D23-D27-D29-D49+D54 -> 954.2646 | E30: =E26+E23-E27-E29-E49+E54 -> 1001.9778 | F30: =F26+F23-F27-F29-F49+F54 -> 1052.0767 | H30: Unlevered Free Cash Flow | I30: =I26+I23-I27-I29-I49+I54 -> 701.77171 | J30: =J26+J23-J27-J29-J49+J54 -> 715.80715 | K30: =K26+K23-K27-K29-K49+K54 -> 730.12329 | L30: =L26+L23-L27-L29-L49+L54 -> 744.72576 | M30: =M26+M23-M27-M29-M49+M54 -> 759.62027
A33: Debt Schedule | H33: Debt Schedule
A34: Metric | B34: 2026E | C34: 2027E | D34: 2028E | E34: 2029E | F34: 2030E | H34: Metric | I34: 2026E | J34: 2027E | K34: 2028E | L34: 2029E | M34: 2030E
A35: Beginning Debt | B35: =Transaction!$F$15 -> 10704.468 | C35: =B43 -> 10385.92 | D35: =C43 -> 10007.817 | E35: =D43 -> 9564.9522 | F35: =E43 -> 9051.7434 | H35: Beginning Debt | I35: =Transaction!$F$15 -> 10704.468 | J35: =I43 -> 10549.695 | K35: =J43 -> 10372.977 | L35: =K43 -> 10172.913 | M35: =L43 -> 9948.0228
A36: Interest Rate | B36: =Inputs!$D$29 -> 0.07 | C36: =Inputs!$D$29 -> 0.07 | D36: =Inputs!$D$29 -> 0.07 | E36: =Inputs!$D$29 -> 0.07 | F36: =Inputs!$D$29 -> 0.07 | H36: Interest Rate | I36: =Inputs!$D$29 -> 0.07 | J36: =Inputs!$D$29 -> 0.07 | K36: =Inputs!$D$29 -> 0.07 | L36: =Inputs!$D$29 -> 0.07 | M36: =Inputs!$D$29 -> 0.07
A37: Cash Interest Expense | B37: =B35*B36 -> 749.31276 | C37: =C35*C36 -> 727.01441 | D37: =D35*D36 -> 700.54721 | E37: =E35*E36 -> 669.54665 | F37: =F35*F36 -> 633.62204 | H37: Cash Interest Expense | I37: =I35*I36 -> 749.31276 | J37: =J35*J36 -> 738.47862 | K37: =K35*K36 -> 726.10838 | L37: =L35*L36 -> 712.10389 | M37: =M35*M36 -> 696.36159
A38: Cash Flow After Interest | B38: =B30-B37*(1-B25) -> 318.5478 | C38: =C30-C37*(1-C25) -> 378.1029 | D38: =D30-D37*(1-D25) -> 442.86513 | E38: =E30-E37*(1-E25) -> 513.20877 | F38: =F30-F37*(1-F25) -> 589.53263 | H38: Cash Flow After Interest | I38: =I30-I37*(1-I25) -> 154.7734 | J38: =J30-J37*(1-J25) -> 176.71775 | K38: =K30-K37*(1-K25) -> 200.06417 | L38: =L30-L37*(1-L25) -> 224.88992 | M38: =M30-M37*(1-M25) -> 251.27631
A39: Mandatory Amortization | B39: =MIN(B35,Transaction!$F$15*Inputs!$D$30) -> 107.04468 | C39: =MIN(C35,Transaction!$F$15*Inputs!$D$30) -> 107.04468 | D39: =MIN(D35,Transaction!$F$15*Inputs!$D$30) -> 107.04468 | E39: =MIN(E35,Transaction!$F$15*Inputs!$D$30) -> 107.04468 | F39: =MIN(F35,Transaction!$F$15*Inputs!$D$30) -> 107.04468 | H39: Mandatory Amortization | I39: =MIN(I35,Transaction!$F$15*Inputs!$D$30) -> 107.04468 | J39: =MIN(J35,Transaction!$F$15*Inputs!$D$30) -> 107.04468 | K39: =MIN(K35,Transaction!$F$15*Inputs!$D$30) -> 107.04468 | L39: =MIN(L35,Transaction!$F$15*Inputs!$D$30) -> 107.04468 | M39: =MIN(M35,Transaction!$F$15*Inputs!$D$30) -> 107.04468
A40: Cash Available for Sweep | B40: =MAX(0,B38-B39) -> 211.50312 | C40: =MAX(0,C38-C39) -> 271.05822 | D40: =MAX(0,D38-D39) -> 335.82045 | E40: =MAX(0,E38-E39) -> 406.16409 | F40: =MAX(0,F38-F39) -> 482.48795 | H40: Cash Available for Sweep | I40: =MAX(0,I38-I39) -> 47.728718 | J40: =MAX(0,J38-J39) -> 69.673073 | K40: =MAX(0,K38-K39) -> 93.019493 | L40: =MAX(0,L38-L39) -> 117.84524 | M40: =MAX(0,M38-M39) -> 144.23163
A41: Cash Sweep % | B41: =Inputs!$D$31 -> 1 | C41: =Inputs!$D$31 -> 1 | D41: =Inputs!$D$31 -> 1 | E41: =Inputs!$D$31 -> 1 | F41: =Inputs!$D$31 -> 1 | H41: Cash Sweep % | I41: =Inputs!$D$31 -> 1 | J41: =Inputs!$D$31 -> 1 | K41: =Inputs!$D$31 -> 1 | L41: =Inputs!$D$31 -> 1 | M41: =Inputs!$D$31 -> 1
A42: Optional Debt Repayment | B42: =MIN(MAX(0,B35-B39),B40*B41) -> 211.50312 | C42: =MIN(MAX(0,C35-C39),C40*C41) -> 271.05822 | D42: =MIN(MAX(0,D35-D39),D40*D41) -> 335.82045 | E42: =MIN(MAX(0,E35-E39),E40*E41) -> 406.16409 | F42: =MIN(MAX(0,F35-F39),F40*F41) -> 482.48795 | H42: Optional Debt Repayment | I42: =MIN(MAX(0,I35-I39),I40*I41) -> 47.728718 | J42: =MIN(MAX(0,J35-J39),J40*J41) -> 69.673073 | K42: =MIN(MAX(0,K35-K39),K40*K41) -> 93.019493 | L42: =MIN(MAX(0,L35-L39),L40*L41) -> 117.84524 | M42: =MIN(MAX(0,M35-M39),M40*M41) -> 144.23163
A43: Ending Debt | B43: =B35-B39-B42 -> 10385.92 | C43: =C35-C39-C42 -> 10007.817 | D43: =D35-D39-D42 -> 9564.9522 | E43: =E35-E39-E42 -> 9051.7434 | F43: =F35-F39-F42 -> 8462.2108 | H43: Ending Debt | I43: =I35-I39-I42 -> 10549.695 | J43: =J35-J39-J42 -> 10372.977 | K43: =K35-K39-K42 -> 10172.913 | L43: =L35-L39-L42 -> 9948.0228 | M43: =M35-M39-M42 -> 9696.7464
A44: DSCR | B44: =(B38+B37)/(B37+B39) -> 1.24698 | C44: =(C38+C37)/(C37+C39) -> 1.3249868 | D44: =(D38+D37)/(D37+D39) -> 1.4158294 | E44: =(E38+E37)/(E37+E39) -> 1.5230088 | F44: =(F38+F37)/(F37+F39) -> 1.6514238 | H44: DSCR | I44: =(I38+I37)/(I37+I39) -> 1.0557346 | J44: =(J38+J37)/(J37+J39) -> 1.0824023 | K44: =(K38+K37)/(K37+K39) -> 1.1116475 | L44: =(L38+L37)/(L37+L39) -> 1.1438631 | M44: =(M38+M37)/(M37+M39) -> 1.1795251
A45: Debt Roll-forward Check | B45: =B35-B39-B42-B43 -> 0 | C45: =C35-C39-C42-C43 -> 0 | D45: =D35-D39-D42-D43 -> 0 | E45: =E35-E39-E42-E43 -> 0 | F45: =F35-F39-F42-F43 -> 0 | H45: Debt Roll-forward Check | I45: =I35-I39-I42-I43 -> 0 | J45: =J35-J39-J42-J43 -> 0 | K45: =K35-K39-K42-K43 -> 0 | L45: =L35-L39-L42-L43 -> 0 | M45: =M35-M39-M42-M43 -> 0
A47: Subscriber Cash Adjustments | H47: Subscriber Cash Adjustments
B48: =B20 -> 2026E | C48: =C20 -> 2027E | D48: =D20 -> 2028E | E48: =E20 -> 2029E | F48: =F20 -> 2030E | I48: =I20 -> 2026E | J48: =J20 -> 2027E | K48: =K20 -> 2028E | L48: =L20 -> 2029E | M48: =M20 -> 2030E
A49: Dealer-account purchases | B49: =B21*Inputs!$I$14 -> 626.30715 | C49: =C21*Inputs!$I$14 -> 657.62251 | D49: =D21*Inputs!$I$14 -> 690.50363 | E49: =E21*Inputs!$I$14 -> 725.02881 | F49: =F21*Inputs!$I$14 -> 761.28026 | H49: Dealer-account purchases | I49: =I21*Inputs!$I$14 -> 608.41266 | J49: =J21*Inputs!$I$14 -> 620.58091 | K49: =K21*Inputs!$I$14 -> 632.99253 | L49: =L21*Inputs!$I$14 -> 645.65238 | M49: =M21*Inputs!$I$14 -> 658.56543
A50: Cost amortization add-back | B50: =B21*Inputs!$I$15 -> 265.18065 | C50: =C21*Inputs!$I$15 -> 278.43968 | D50: =D21*Inputs!$I$15 -> 292.36167 | E50: =E21*Inputs!$I$15 -> 306.97975 | F50: =F21*Inputs!$I$15 -> 322.32874 | H50: Cost amortization add-back | I50: =I21*Inputs!$I$15 -> 257.60406 | J50: =J21*Inputs!$I$15 -> 262.75614 | K50: =K21*Inputs!$I$15 -> 268.01126 | L50: =L21*Inputs!$I$15 -> 273.37149 | M50: =M21*Inputs!$I$15 -> 278.83892
...
